<?xml version="1.0"?>
<robot name="robot_name">

  <!-- Base link -->
<link name="base_link">
  <visual>
    <origin xyz="0 0 0.1" rpy="0 0 0"/>
    <geometry>
      <cylinder radius="0.3" length="0.1"/>
    </geometry>
    <material name="chassis_grey">
      <color rgba="0.5 0.5 0.5 1.0"/>
    </material>
  </visual>

  <collision>
    <origin xyz="0 0 0.1" rpy="0 0 0"/>
    <geometry>
      <cylinder radius="0.3" length="0.1"/>
    </geometry>
  </collision>

  <inertial>
    <mass value="20.0"/>
    <origin xyz="0 0 0" rpy="0 0 0"/>
    <inertia ixx="1.0" ixy="0" ixz="0" iyy="1.5" iyz="0" izz="2.0"/>
  </inertial>
</link>


  <!-- Drive wheels -->
  
  <!-- Left Wheel Link -->
  <link name="left_wheel_link">
    <visual>
      <origin xyz="0 0 0" rpy="1.5708 0 3.1416"/>
      <geometry>
        <cylinder radius="0.1" length="0.1"/>
      </geometry>
      <material name="wheel_grey_l">
        <color rgba="0.5 0.5 0.5 1.0"/>
      </material>
    </visual>
    <collision>
      <origin xyz="0 0 0" rpy="1.5708 0 3.1416"/>
      <geometry>
        <cylinder radius="0.1" length="0.1"/>
      </geometry>
    </collision>
    <inertial>
      <mass value="2.0"/>
      <origin xyz="0 0 0" rpy="0 0 0"/>
      <inertia ixx="0.01" ixy="0" ixz="0" iyy="0.01" iyz="0" izz="0.02"/>
    </inertial>
  </link>

  <joint name="left_wheel_joint" type="continuous">
    <parent link="base_link"/>
    <child link="left_wheel_link"/>
    <origin xyz="0.0 -0.35 0.1" rpy="0 0 0"/>
    <axis xyz="0 1 0"/>
  </joint>
  
   
  
  <!-- Right Wheel Link -->
  <link name="right_wheel_link">
    <visual>
      <origin xyz="0 0 0" rpy="1.5708 0 3.1416"/>
      <geometry>
        <cylinder radius="0.1" length="0.1"/>
      </geometry>
      <material name="wheel_grey_r">
        <color rgba="0.5 0.5 0.5 1.0"/>
      </material>
    </visual>
    <collision>
      <origin xyz="0 0 0" rpy="1.5708 0 3.1416"/>
      <geometry>
       <cylinder radius="0.1" length="0.1"/>
      </geometry>
    </collision>
    <inertial>
      <mass value="2.0"/>
      <origin xyz="0 0 0" rpy="0 0 0"/>
      <inertia ixx="0.01" ixy="0" ixz="0" iyy="0.01" iyz="0" izz="0.02"/>
    </inertial>
  </link>

  <joint name="right_wheel_joint" type="continuous">
    <parent link="base_link"/>
    <child link="right_wheel_link"/>
    <origin xyz="0.0 0.35 0.1" rpy="0 0 0"/>
    <axis xyz="0 1 0"/>
    
  </joint>
  
    
  <!-- ZED IMU -->
  <joint name="zed_imu_joint" type="fixed">
    <parent link="base_link"/>
    <child link="zed_imu_link"/>
    
    <origin xyz="0 0.0 0.15" rpy="0 0 0"/>
  </joint>

  <link name="zed_imu_link">
    <inertial>
      <mass value="0.05"/>`
      <origin xyz="0 0 0" rpy="0 0 0"/>
      <inertia ixx="1e-5" ixy="0" ixz="0" iyy="1e-5" iyz="0" izz="1e-5"/>
    </inertial>
    <visual>
      <origin xyz="0 0 0" rpy="0 0 0"/>
      <geometry>
        <box size="0.02 0.02 0.02"/>
      </geometry>
      <material name="imu_frame">
        <color rgba="1.0 1.0 0.0 1.0"/>
      </material>
    </visual>
    <collision>
      <origin xyz="0 0 0" rpy="0 0 0"/>
      <geometry>
        <box size="0.02 0.02 0.02"/>
      </geometry>
    </collision>
  </link>
  
  
  
  <!-- Lidar -->
  <link name="rplidar_c1">
    <inertial>
      <origin xyz="0.0 0.0 0.0" rpy="0.0 0.0 0.0"/>
      <mass value="0.4"/>
      <inertia ixx="1e-4" ixy="0.0" ixz="0.0" iyy="1e-4" iyz="0.0" izz="2e-4"/>
    </inertial>
    <visual name="">
      <origin xyz="0.0 0.0 0.0" rpy="0.0 0.0 0.0"/>
      <geometry>
        <cylinder radius="0.1" length="0.1"/>
      </geometry>
      <material name="rplidar_c1">
        <color rgba="1.0 0.0 0.0 1.0"/>
      </material>
    </visual>
    <collision>
      <origin xyz="0.0 0.0 0.0" rpy="0.0 0.0 0.0"/>
      <geometry>
        <cylinder radius="0.1" length="0.1"/>
      </geometry>
    </collision>
  </link>

  <joint name="rplidar_joint" type="fixed">
    <parent link="base_link"/>
    <child link="rplidar_c1"/>
    <origin xyz="0.0 0.0 0.2" rpy="0.0 0.0 0.0"/>
  </joint>
  
  
  
  
  <!-- Plugins -->
  <gazebo>
    <plugin
        filename="gz-sim-diff-drive-system"
        name="gz::sim::systems::DiffDrive">
        <topic>/cmd_vel</topic>

        <left_joint>left_wheel_joint</left_joint>
        <right_joint>right_wheel_joint</right_joint>

        <wheel_separation>0.7</wheel_separation>
        <wheel_radius>0.1</wheel_radius> 

        <max_velocity>3.0</max_velocity> 
        <max_linear_acceleration>1</max_linear_acceleration>
        <min_linear_acceleration>-1</min_linear_acceleration>
        <max_angular_acceleration>2</max_angular_acceleration>
        <min_angular_acceleration>-2</min_angular_acceleration>
        <max_linear_velocity>0.5</max_linear_velocity>
        <min_linear_velocity>-0.5</min_linear_velocity>
        <max_angular_velocity>1</max_angular_velocity>
        <min_angular_velocity>-1</min_angular_velocity>
        
        <odom_topic>/wheel_encoder/odom</odom_topic> 
        <frame_id>odom</frame_id>
        <child_frame_id>base_link</child_frame_id>
        <odom_publish_frequency>60</odom_publish_frequency>
    </plugin>

    <plugin
        filename="gz-sim-joint-state-publisher-system"
        name="gz::sim::systems::JointStatePublisher">
        <topic>joint_states</topic>
        <joint_name>left_wheel_joint</joint_name>
        <joint_name>right_wheel_joint</joint_name>
    </plugin>
  </gazebo>
  
  <!-- IMU Plugin -->
<gazebo>
  <plugin filename="libignition-gazebo-imu-system"
          name="ignition::gazebo::systems::Imu">
  </plugin>
</gazebo>

<gazebo reference="zed_imu_link">
  <sensor name="imu_sensor" type="imu">
    <always_on>1</always_on>
    <update_rate>1000</update_rate>
    <visualize>true</visualize>
    <topic>/zed/zed_node/imu/data_raw</topic>

    <!-- noise -->
    <imu>
      <angular_velocity>
        <x>
          <noise type="gaussian">
            <mean>0.0</mean>
            <stddev>0.05</stddev>
          </noise>
        </x>
        <y>
          <noise type="gaussian">
            <mean>0.0</mean>
            <stddev>0.05</stddev>
          </noise>
        </y>
        <z>
          <noise type="gaussian">
            <mean>0.0</mean>
            <stddev>0.05</stddev>
          </noise>
        </z>
      </angular_velocity>

      <linear_acceleration>
        <x>
          <noise type="gaussian">
            <mean>0.0</mean>
            <stddev>0.1</stddev>
          </noise>
        </x>
        <y>
          <noise type="gaussian">
            <mean>0.0</mean>
            <stddev>0.1</stddev>
          </noise>
        </y>
        <z>
          <noise type="gaussian">
            <mean>0.0</mean>
            <stddev>0.1</stddev> <!-- Becuase I used basic filters I didn't increase it too much.-->
          </noise>
        </z>
      </linear_acceleration>
    </imu>
  </sensor>
</gazebo>

  
  <!-- Lidar Plugin -->
  <gazebo reference="rplidar_c1">
    <sensor type="gpu_lidar" name="rplidar_c1_sensor">
        <always_on>1</always_on>
        <visualize>true</visualize>
        <update_rate>20</update_rate>
        <topic>/gz_lidar/points</topic>
        <frame_id>rplidar_c1</frame_id>
        <lidar>
            <scan>
                <horizontal>
                    <samples>720</samples>
                    <resolution>1</resolution>
                    <min_angle>-3.14</min_angle>
                    <max_angle>3.14</max_angle>
                </horizontal>
            </scan>
            <range>
                <min>0.8</min>
                <max>60.0</max>
                <resolution>0.01</resolution>
            </range>  
            <noise>
                <type>gaussian</type>
                <mean>0.0</mean>
                <stddev>0.01</stddev>
            </noise>
        </lidar>
    </sensor>
  </gazebo>
    
</robot>
